<sdf version='1.7'>
  <world name='world'>
    <scene>
      <ambient>0.8 0.8 0.8 1</ambient>
      <background>0 0 0 1</background>
      <grid>0</grid>
      <shadows>1</shadows>
    </scene>
    <light name='sun' type='directional'>
      <cast_shadows>1</cast_shadows>
      <pose>0 0 10 0 -0 0</pose>
      <diffuse>0.8 0.8 0.8 1</diffuse>
      <specular>0.2 0.2 0.2 1</specular>
      <attenuation>
        <range>1000</range>
        <constant>0.9</constant>
        <linear>0.01</linear>
        <quadratic>0.001</quadratic>
      </attenuation>
      <direction>-0.5 0.1 -0.9</direction>
      <spot>
        <inner_angle>0</inner_angle>
        <outer_angle>0</outer_angle>
        <falloff>0</falloff>
      </spot>
    </light>
    <gui fullscreen='0'>
      <camera name='gui_camera'>
        <pose>-3.13892 -9.8163 13.407 0 0.273141 2.73334</pose>
        <view_controller>orbit</view_controller>
        <projection_type>perspective</projection_type>
      </camera>
      <plugin name='toggle_charging' filename='libtoggle_charging.so'/>
      <plugin name='toggle_floors' filename='libtoggle_floors.so'>
        <floor name='L1' model_name='building_L1'>
          <model name='Fridge'/>
          <model name='OfficeChairGrey'/>
          <model name='AdjTable'/>
          <model name='AdjTable_2'/>
          <model name='AdjTable_3'/>
          <model name='AdjTable_4'/>
          <model name='Drawer'/>
          <model name='BigCubicle'/>
          <model name='BigCubicle_2'/>
          <model name='BigCubicle_3'/>
          <model name='BigCubicle_4'/>
          <model name='AdjTable_5'/>
          <model name='AdjTable_6'/>
          <model name='AdjTable_7'/>
          <model name='AdjTable_8'/>
          <model name='AdjTable_9'/>
          <model name='AdjTable_10'/>
          <model name='Drawer_2'/>
          <model name='Drawer_3'/>
          <model name='ConfTable'/>
          <model name='RecTable'/>
          <model name='WhiteCabinet'/>
          <model name='SquareShelf'/>
          <model name='coke_dispenser'/>
          <model name='coke_ingestor'/>
          <model name='main_door'/>
          <model name='coe_door'/>
          <model name='hardware_door'/>
        </floor>
      </plugin>
    </gui>
    <model name='Fridge'>
      <static>1</static>
      <link name='body'>
        <pose>0 0 0 0 -0 0</pose>
        <visual name='visual'>
          <geometry>
            <mesh>
              <uri>model://Fridge/meshes/Fridge.obj</uri>
            </mesh>
          </geometry>
        </visual>
        <collision name='collision'>
          <geometry>
            <mesh>
              <uri>model://Fridge/meshes/Fridge_Col.obj</uri>
            </mesh>
          </geometry>
          <max_contacts>10</max_contacts>
          <surface>
            <contact>
              <ode/>
            </contact>
            <bounce/>
            <friction>
              <torsional>
                <ode/>
              </torsional>
              <ode/>
            </friction>
          </surface>
        </collision>
        <self_collide>0</self_collide>
        <enable_wind>0</enable_wind>
        <kinematic>0</kinematic>
      </link>
      <pose>15.9881 -5.75084 0 0 -0 1.5708</pose>
    </model>
    <model name='OfficeChairGrey'>
      <static>1</static>
      <link name='body'>
        <pose>0 0 0 0 -0 0</pose>
        <visual name='visual'>
          <geometry>
            <mesh>
              <uri>model://OfficeChairGrey/meshes/OfficeChairGrey.obj</uri>
            </mesh>
          </geometry>
        </visual>
        <collision name='collision'>
          <geometry>
            <mesh>
              <uri>model://OfficeChairGrey/meshes/OfficeChairGrey_Col.obj</uri>
            </mesh>
          </geometry>
          <max_contacts>10</max_contacts>
          <surface>
            <contact>
              <ode/>
            </contact>
            <bounce/>
            <friction>
              <torsional>
                <ode/>
              </torsional>
              <ode/>
            </friction>
          </surface>
        </collision>
        <self_collide>0</self_collide>
        <enable_wind>0</enable_wind>
        <kinematic>0</kinematic>
      </link>
      <pose>14.2558 -5.54694 0 0 -0 0.0166</pose>
    </model>
    <model name='AdjTable'>
      <static>1</static>
      <link name='body'>
        <pose>0 0 0 0 -0 0</pose>
        <visual name='visual'>
          <geometry>
            <mesh>
              <uri>model://AdjTable/meshes/AdjTable.obj</uri>
            </mesh>
          </geometry>
        </visual>
        <collision name='collision'>
          <geometry>
            <mesh>
              <uri>model://AdjTable/meshes/AdjTable_Col.obj</uri>
            </mesh>
          </geometry>
          <max_contacts>10</max_contacts>
          <surface>
            <contact>
              <ode/>
            </contact>
            <bounce/>
            <friction>
              <torsional>
                <ode/>
              </torsional>
              <ode/>
            </friction>
          </surface>
        </collision>
        <self_collide>0</self_collide>
        <enable_wind>0</enable_wind>
        <kinematic>0</kinematic>
      </link>
      <pose>11.7885 -5.97975 0 0 -0 -3.12188</pose>
    </model>
    <model name='AdjTable_3'>
      <static>1</static>
      <link name='body'>
        <pose>0 0 0 0 -0 0</pose>
        <visual name='visual'>
          <geometry>
            <mesh>
              <uri>model://AdjTable/meshes/AdjTable.obj</uri>
            </mesh>
          </geometry>
        </visual>
        <collision name='collision'>
          <geometry>
            <mesh>
              <uri>model://AdjTable/meshes/AdjTable_Col.obj</uri>
            </mesh>
          </geometry>
          <max_contacts>10</max_contacts>
          <surface>
            <contact>
              <ode/>
            </contact>
            <bounce/>
            <friction>
              <torsional>
                <ode/>
              </torsional>
              <ode/>
            </friction>
          </surface>
        </collision>
        <self_collide>0</self_collide>
        <enable_wind>0</enable_wind>
        <kinematic>0</kinematic>
      </link>
      <pose>14.2449 -5.94148 0 0 -0 -3.12378</pose>
    </model>
    <model name='AdjTable_4'>
      <static>1</static>
      <link name='body'>
        <pose>0 0 0 0 -0 0</pose>
        <visual name='visual'>
          <geometry>
            <mesh>
              <uri>model://AdjTable/meshes/AdjTable.obj</uri>
            </mesh>
          </geometry>
        </visual>
        <collision name='collision'>
          <geometry>
            <mesh>
              <uri>model://AdjTable/meshes/AdjTable_Col.obj</uri>
            </mesh>
          </geometry>
          <max_contacts>10</max_contacts>
          <surface>
            <contact>
              <ode/>
            </contact>
            <bounce/>
            <friction>
              <torsional>
                <ode/>
              </torsional>
              <ode/>
            </friction>
          </surface>
        </collision>
        <self_collide>0</self_collide>
        <enable_wind>0</enable_wind>
        <kinematic>0</kinematic>
      </link>
      <pose>6.73419 -9.67534 0 0 -0 1.0878</pose>
    </model>
    <model name='Drawer'>
      <static>1</static>
      <link name='body'>
        <pose>0 0 0 0 -0 0</pose>
        <visual name='visual'>
          <geometry>
            <mesh>
              <uri>model://Drawer/meshes/Drawer.obj</uri>
            </mesh>
          </geometry>
        </visual>
        <collision name='collision'>
          <geometry>
            <mesh>
              <uri>model://Drawer/meshes/Drawer.obj</uri>
            </mesh>
          </geometry>
          <max_contacts>10</max_contacts>
          <surface>
            <contact>
              <ode/>
            </contact>
            <bounce/>
            <friction>
              <torsional>
                <ode/>
              </torsional>
              <ode/>
            </friction>
          </surface>
        </collision>
        <self_collide>0</self_collide>
        <enable_wind>0</enable_wind>
        <kinematic>0</kinematic>
      </link>
      <pose>6.11121 -10.5644 0 0 -0 1.1104</pose>
    </model>
    <model name='AdjTable_10'>
      <static>1</static>
      <link name='body'>
        <pose>0 0 0 0 -0 0</pose>
        <visual name='visual'>
          <geometry>
            <mesh>
              <uri>model://AdjTable/meshes/AdjTable.obj</uri>
            </mesh>
          </geometry>
        </visual>
        <collision name='collision'>
          <geometry>
            <mesh>
              <uri>model://AdjTable/meshes/AdjTable_Col.obj</uri>
            </mesh>
          </geometry>
          <max_contacts>10</max_contacts>
          <surface>
            <contact>
              <ode/>
            </contact>
            <bounce/>
            <friction>
              <torsional>
                <ode/>
              </torsional>
              <ode/>
            </friction>
          </surface>
        </collision>
        <self_collide>0</self_collide>
        <enable_wind>0</enable_wind>
        <kinematic>0</kinematic>
      </link>
      <pose>13.0065 -5.56573 0 0 -0 1.5914</pose>
    </model>
    <model name='OfficeChairGrey_11'>
      <static>1</static>
      <link name='body'>
        <pose>0 0 0 0 -0 0</pose>
        <visual name='visual'>
          <geometry>
            <mesh>
              <uri>model://OfficeChairGrey/meshes/OfficeChairGrey.obj</uri>
            </mesh>
          </geometry>
        </visual>
        <collision name='collision'>
          <geometry>
            <mesh>
              <uri>model://OfficeChairGrey/meshes/OfficeChairGrey_Col.obj</uri>
            </mesh>
          </geometry>
          <max_contacts>10</max_contacts>
          <surface>
            <contact>
              <ode/>
            </contact>
            <bounce/>
            <friction>
              <torsional>
                <ode/>
              </torsional>
              <ode/>
            </friction>
          </surface>
        </collision>
        <self_collide>0</self_collide>
        <enable_wind>0</enable_wind>
        <kinematic>0</kinematic>
      </link>
      <pose>11.8429 -5.56464 0 0 -0 0.016</pose>
    </model>
    <model name='ConfTable'>
      <static>1</static>
      <link name='body'>
        <pose>0 0 0 0 -0 0</pose>
        <visual name='visual'>
          <geometry>
            <mesh>
              <uri>model://ConfTable/meshes/ConfTable.obj</uri>
            </mesh>
          </geometry>
        </visual>
        <collision name='collision'>
          <geometry>
            <mesh>
              <uri>model://ConfTable/meshes/ConfTable_Col.obj</uri>
            </mesh>
          </geometry>
          <max_contacts>10</max_contacts>
          <surface>
            <contact>
              <ode/>
            </contact>
            <bounce/>
            <friction>
              <torsional>
                <ode/>
              </torsional>
              <ode/>
            </friction>
          </surface>
        </collision>
        <self_collide>0</self_collide>
        <enable_wind>0</enable_wind>
        <kinematic>0</kinematic>
      </link>
      <pose>5.24861 -7.38191 0 0 -0 1.1017</pose>
    </model>
    <model name='RecTable'>
      <static>1</static>
      <link name='body'>
        <pose>0 0 0 0 -0 0</pose>
        <visual name='visual'>
          <geometry>
            <mesh>
              <uri>model://RecTable/meshes/RecTable.obj</uri>
            </mesh>
          </geometry>
        </visual>
        <collision name='collision'>
          <geometry>
            <mesh>
              <uri>model://RecTable/meshes/RecTable_Col.obj</uri>
            </mesh>
          </geometry>
          <max_contacts>10</max_contacts>
          <surface>
            <contact>
              <ode/>
            </contact>
            <bounce/>
            <friction>
              <torsional>
                <ode/>
              </torsional>
              <ode/>
            </friction>
          </surface>
        </collision>
        <self_collide>0</self_collide>
        <enable_wind>0</enable_wind>
        <kinematic>0</kinematic>
      </link>
      <pose>21.8765 -4.46735 0 0 -0 0</pose>
    </model>
    <model name='coke_dispenser'>
      <pose>17.7044 -5.28942 0 0 -0 1.5708</pose>
      <static>1</static>
      <link name='visual_link'>
        <pose>0 0 0.05 0 -0 0</pose>
        <visual name='visual'>
          <geometry>
            <box>
              <size>0.1 0.1 0.1</size>
            </box>
          </geometry>
          <material>
            <ambient>0.8 0.8 0.8 0.1</ambient>
            <diffuse>0.8 0.8 0.8 0.1</diffuse>
          </material>
        </visual>
        <self_collide>0</self_collide>
        <enable_wind>0</enable_wind>
        <kinematic>0</kinematic>
      </link>
      <plugin name='teleport_dispenser' filename='libteleport_dispenser.so'/>
    </model>
    <model name='Coke'>
      <static>0</static>
      <link name='body'>
        <pose>0 0 0 0 -0 0</pose>
        <visual name='visual'>
          <geometry>
            <mesh>
              <uri>model://Coke/meshes/coke.obj</uri>
            </mesh>
          </geometry>
        </visual>
        <collision name='collision'>
          <geometry>
            <mesh>
              <uri>model://Coke/meshes/coke.obj</uri>
            </mesh>
          </geometry>
          <max_contacts>10</max_contacts>
          <surface>
            <contact>
              <ode/>
            </contact>
            <bounce/>
            <friction>
              <torsional>
                <ode/>
              </torsional>
              <ode/>
            </friction>
          </surface>
        </collision>
        <inertial>
          <mass>1</mass>
          <inertia>
            <ixx>0.00336667</ixx>
            <iyy>0.000866667</iyy>
            <izz>0.00416667</izz>
            <ixy>0</ixy>
            <ixz>0</ixz>
            <iyz>0</iyz>
          </inertia>
          <pose>0 0 0 0 -0 0</pose>
        </inertial>
        <self_collide>0</self_collide>
        <enable_wind>0</enable_wind>
        <kinematic>0</kinematic>
      </link>
      <pose>17.7044 -5.29153 0 0 -0 1.5708</pose>
    </model>
    <model name='coke_ingestor'>
      <pose>22.5427 -7.61045 0.805 0 -0 1.5708</pose>
      <static>1</static>
      <link name='visual_link'>
        <pose>0 0 0.05 0 -0 0</pose>
        <visual name='visual'>
          <geometry>
            <box>
              <size>0.1 0.1 0.1</size>
            </box>
          </geometry>
          <material>
            <ambient>0.8 0.8 0.8 0.1</ambient>
            <diffuse>0.8 0.8 0.8 0.1</diffuse>
          </material>
        </visual>
        <self_collide>0</self_collide>
        <enable_wind>0</enable_wind>
        <kinematic>0</kinematic>
      </link>
      <plugin name='teleport_ingestor' filename='libteleport_ingestor.so'/>
    </model>
    <model name='tinyRobot1'>
      <plugin name='slotcar' filename='libslotcar.so'>
        <nominal_drive_speed>0.5</nominal_drive_speed>
        <nominal_drive_acceleration>0.25</nominal_drive_acceleration>
        <max_drive_acceleration>0.75</max_drive_acceleration>
        <nominal_turn_speed>0.6</nominal_turn_speed>
        <nominal_turn_acceleration>1.5</nominal_turn_acceleration>
        <max_turn_acceleration>2.0</max_turn_acceleration>
        <tire_radius>0.1</tire_radius>
        <base_width>0.3206</base_width>
        <stop_distance>0.75</stop_distance>
        <stop_radius>0.75</stop_radius>
        <nominal_voltage>12.0</nominal_voltage>
        <nominal_capacity>24.0</nominal_capacity>
        <charging_current>5.0</charging_current>
        <mass>20.0</mass>
        <inertia>10.0</inertia>
        <friction_coefficient>0.22</friction_coefficient>
        <nominal_power>20.0</nominal_power>
      </plugin>
      <link name='base_footprint'>
        <pose>0 0 0 0 -0 0</pose>
        <inertial>
          <pose>-0.15 0 0.13 0 -0 0</pose>
          <mass>7</mass>
          <inertia>
            <ixx>0.0594508</ixx>
            <ixy>0</ixy>
            <ixz>-2.77556e-17</ixz>
            <iyy>0.150753</iyy>
            <iyz>0</iyz>
            <izz>0.172704</izz>
          </inertia>
        </inertial>
        <collision name='base_footprint_fixed_joint_lump__base_link_collision'>
          <pose>-0.11 0 0.151 0 -0 0</pose>
          <geometry>
            <box>
              <size>0.398 0.268 0.16</size>
            </box>
          </geometry>
          <max_contacts>10</max_contacts>
          <surface>
            <contact>
              <ode/>
            </contact>
            <bounce/>
            <friction>
              <torsional>
                <ode/>
              </torsional>
              <ode/>
            </friction>
          </surface>
        </collision>
        <collision name='base_footprint_fixed_joint_lump__base_link_collision_1'>
          <pose>-0.136 0 0.248 0 -0 0</pose>
          <geometry>
            <box>
              <size>0.375 0.268 0.034</size>
            </box>
          </geometry>
          <max_contacts>10</max_contacts>
          <surface>
            <contact>
              <ode/>
            </contact>
            <bounce/>
            <friction>
              <torsional>
                <ode/>
              </torsional>
              <ode/>
            </friction>
          </surface>
        </collision>
        <collision name='base_footprint_fixed_joint_lump__base_link_collision_2'>
          <pose>-0.279 0.169 0.106 0 -0 0</pose>
          <geometry>
            <box>
              <size>0.1 0.07 0.07</size>
            </box>
          </geometry>
          <max_contacts>10</max_contacts>
          <surface>
            <contact>
              <ode/>
            </contact>
            <bounce/>
            <friction>
              <torsional>
                <ode/>
              </torsional>
              <ode/>
            </friction>
          </surface>
        </collision>
        <collision name='base_footprint_fixed_joint_lump__base_link_collision_3'>
          <pose>-0.279 -0.169 0.106 0 -0 0</pose>
          <geometry>
            <box>
              <size>0.1 0.07 0.07</size>
            </box>
          </geometry>
          <max_contacts>10</max_contacts>
          <surface>
            <contact>
              <ode/>
            </contact>
            <bounce/>
            <friction>
              <torsional>
                <ode/>
              </torsional>
              <ode/>
            </friction>
          </surface>
        </collision>
        <collision name='base_footprint_fixed_joint_lump__left_caster_wheel_collision_4'>
          <pose>-0.3 0.169 0.04 0 -0 0</pose>
          <geometry>
            <sphere>
              <radius>0.04</radius>
            </sphere>
          </geometry>
          <surface>
            <contact>
              <ode>
                <kp>1e+08</kp>
                <min_depth>0.005</min_depth>
              </ode>
            </contact>
            <friction>
              <ode>
                <mu>0</mu>
                <mu2>0</mu2>
              </ode>
              <torsional>
                <ode/>
              </torsional>
            </friction>
            <bounce/>
          </surface>
          <max_contacts>10</max_contacts>
        </collision>
        <collision name='base_footprint_fixed_joint_lump__raspicam_collision_5'>
          <pose>0.05 0.085 0.245 0 -1.15192 3.1415</pose>
          <geometry>
            <box>
              <size>0.03 0.026 0.016</size>
            </box>
          </geometry>
          <max_contacts>10</max_contacts>
          <surface>
            <contact>
              <ode/>
            </contact>
            <bounce/>
            <friction>
              <torsional>
                <ode/>
              </torsional>
              <ode/>
            </friction>
          </surface>
        </collision>
        <collision name='base_footprint_fixed_joint_lump__right_caster_wheel_collision_6'>
          <pose>-0.3 -0.169 0.04 0 -0 0</pose>
          <geometry>
            <sphere>
              <radius>0.04</radius>
            </sphere>
          </geometry>
          <surface>
            <contact>
              <ode>
                <kp>1e+08</kp>
                <min_depth>0.005</min_depth>
              </ode>
            </contact>
            <friction>
              <ode>
                <mu>0</mu>
                <mu2>0</mu2>
              </ode>
              <torsional>
                <ode/>
              </torsional>
            </friction>
            <bounce/>
          </surface>
          <max_contacts>10</max_contacts>
        </collision>
        <collision name='base_footprint_fixed_joint_lump__sonar_0_collision_7'>
          <pose>0.01 -0.14 0.25 0 0 -1.5708</pose>
          <geometry>
            <box>
              <size>0.02 0.044 0.021</size>
            </box>
          </geometry>
          <surface>
            <contact>
              <ode/>
            </contact>
            <friction>
              <ode/>
              <torsional>
                <ode/>
              </torsional>
            </friction>
            <bounce/>
          </surface>
          <max_contacts>10</max_contacts>
        </collision>
        <collision name='base_footprint_fixed_joint_lump__sonar_1_collision_8'>
          <pose>0.08 -0.07 0.25 0 -0 0.785</pose>
          <geometry>
            <box>
              <size>0.02 0.044 0.021</size>
            </box>
          </geometry>
          <surface>
            <contact>
              <ode/>
            </contact>
            <friction>
              <ode/>
              <torsional>
                <ode/>
              </torsional>
            </friction>
            <bounce/>
          </surface>
          <max_contacts>10</max_contacts>
        </collision>
        <collision name='base_footprint_fixed_joint_lump__sonar_2_collision_9'>
          <pose>0.08 -0.01 0.25 0 0 -0.785</pose>
          <geometry>
            <box>
              <size>0.02 0.044 0.021</size>
            </box>
          </geometry>
          <surface>
            <contact>
              <ode/>
            </contact>
            <friction>
              <ode/>
              <torsional>
                <ode/>
              </torsional>
            </friction>
            <bounce/>
          </surface>
          <max_contacts>10</max_contacts>
        </collision>
        <collision name='base_footprint_fixed_joint_lump__sonar_3_collision_10'>
          <pose>0.08 0.04 0.25 0 -0 0</pose>
          <geometry>
            <box>
              <size>0.02 0.044 0.021</size>
            </box>
          </geometry>
          <surface>
            <contact>
              <ode/>
            </contact>
            <friction>
              <ode/>
              <torsional>
                <ode/>
              </torsional>
            </friction>
            <bounce/>
          </surface>
          <max_contacts>10</max_contacts>
        </collision>
        <collision name='base_footprint_fixed_joint_lump__sonar_4_collision_11'>
          <pose>0.01 0.14 0.25 0 -0 1.5708</pose>
          <geometry>
            <box>
              <size>0.02 0.044 0.021</size>
            </box>
          </geometry>
          <surface>
            <contact>
              <ode/>
            </contact>
            <friction>
              <ode/>
              <torsional>
                <ode/>
              </torsional>
            </friction>
            <bounce/>
          </surface>
          <max_contacts>10</max_contacts>
        </collision>
        <visual name='base_footprint_fixed_joint_lump__base_link_visual'>
          <pose>-0.11 0 0.071 0 -0 0</pose>
          <geometry>
            <mesh>
              <scale>1 1 1</scale>
              <uri>model://TinyRobot/meshes/tinyRobot_body.dae</uri>
            </mesh>
          </geometry>
        </visual>
        <visual name='base_footprint_fixed_joint_lump__base_link_visual_1'>
          <pose>-0.279 0.17 0.09 0 -0 -3.14159</pose>
          <geometry>
            <mesh>
              <scale>1 1 1</scale>
              <uri>model://TinyRobot/meshes/caster_wheel.dae</uri>
            </mesh>
          </geometry>
        </visual>
        <visual name='base_footprint_fixed_joint_lump__base_link_visual_2'>
          <pose>-0.279 -0.17 0.09 0 -0 -3.14159</pose>
          <geometry>
            <mesh>
              <scale>1 1 1</scale>
              <uri>model://TinyRobot/meshes/caster_wheel.dae</uri>
            </mesh>
          </geometry>
        </visual>
        <velocity_decay/>
        <velocity_decay/>
        <velocity_decay/>
        <velocity_decay/>
        <self_collide>0</self_collide>
        <enable_wind>0</enable_wind>
        <kinematic>0</kinematic>
      </link>
      <link name='left_wheel'>
        <pose>0 0.163 0.1 0 -0 1.5708</pose>
        <inertial>
          <pose>0 0 0 3.14159 1.57079 3.14159</pose>
          <mass>3.34</mass>
          <inertia>
            <ixx>0.00904583</ixx>
            <ixy>0</ixy>
            <ixz>0</ixz>
            <iyy>0.00904583</iyy>
            <iyz>0</iyz>
            <izz>0.0167</izz>
          </inertia>
        </inertial>
        <collision name='left_wheel_collision'>
          <pose>0 0 0 3.14159 1.57079 3.14159</pose>
          <geometry>
            <sphere>
              <radius>0.1</radius>
            </sphere>
          </geometry>
          <surface>
            <contact>
              <ode>
                <kp>1e+07</kp>
                <kd>1</kd>
              </ode>
            </contact>
            <friction>
              <ode>
                <mu>1</mu>
                <mu2>1</mu2>
                <fdir1>0 0 1</fdir1>
              </ode>
              <torsional>
                <ode/>
              </torsional>
            </friction>
            <bounce/>
          </surface>
          <max_contacts>10</max_contacts>
        </collision>
        <visual name='left_wheel_visual'>
          <pose>-0.071 0 0 0 -0 0</pose>
          <geometry>
            <mesh>
              <scale>1 1 1</scale>
              <uri>model://TinyRobot/meshes/front_wheel.dae</uri>
            </mesh>
          </geometry>
        </visual>
        <gravity>1</gravity>
        <velocity_decay/>
        <self_collide>0</self_collide>
        <enable_wind>0</enable_wind>
        <kinematic>0</kinematic>
      </link>
      <joint name='joint_tire_left' type='revolute'>
        <child>left_wheel</child>
        <parent>base_footprint</parent>
        <axis>
          <xyz expressed_in='__model__'>0 1 0</xyz>
          <limit>
            <lower>-1e+16</lower>
            <upper>1e+16</upper>
          </limit>
          <dynamics>
            <spring_reference>0</spring_reference>
            <spring_stiffness>0</spring_stiffness>
          </dynamics>
        </axis>
      </joint>
      <link name='right_wheel'>
        <pose>0 -0.163 0.1 0 -0 1.5708</pose>
        <inertial>
          <pose>0 0 0 3.14159 1.57079 3.14159</pose>
          <mass>3.34</mass>
          <inertia>
            <ixx>0.00904583</ixx>
            <ixy>0</ixy>
            <ixz>0</ixz>
            <iyy>0.00904583</iyy>
            <iyz>0</iyz>
            <izz>0.0167</izz>
          </inertia>
        </inertial>
        <collision name='right_wheel_collision'>
          <pose>0 0 0 3.14159 1.57079 3.14159</pose>
          <geometry>
            <sphere>
              <radius>0.1</radius>
            </sphere>
          </geometry>
          <surface>
            <contact>
              <ode>
                <kp>1e+07</kp>
                <kd>1</kd>
              </ode>
            </contact>
            <friction>
              <ode>
                <mu>1</mu>
                <mu2>1</mu2>
                <fdir1>0 0 1</fdir1>
              </ode>
              <torsional>
                <ode/>
              </torsional>
            </friction>
            <bounce/>
          </surface>
          <max_contacts>10</max_contacts>
        </collision>
        <visual name='right_wheel_visual'>
          <pose>0.071 0 0 -3.14159 -0 -3.14159</pose>
          <geometry>
            <mesh>
              <scale>1 1 1</scale>
              <uri>model://TinyRobot/meshes/front_wheel.dae</uri>
            </mesh>
          </geometry>
        </visual>
        <gravity>1</gravity>
        <velocity_decay/>
        <self_collide>0</self_collide>
        <enable_wind>0</enable_wind>
        <kinematic>0</kinematic>
      </link>
      <joint name='joint_tire_right' type='revolute'>
        <child>right_wheel</child>
        <parent>base_footprint</parent>
        <axis>
          <xyz expressed_in='__model__'>0 1 0</xyz>
          <limit>
            <lower>-1e+16</lower>
            <upper>1e+16</upper>
          </limit>
          <dynamics>
            <spring_reference>0</spring_reference>
            <spring_stiffness>0</spring_stiffness>
          </dynamics>
        </axis>
      </joint>
      <static>0</static>
      <pose>10.4331 -5.5751 0 0 -0 1.32862</pose>
    </model>
    <model name='tinyRobot2'>
      <plugin name='slotcar' filename='libslotcar.so'>
        <nominal_drive_speed>0.5</nominal_drive_speed>
        <nominal_drive_acceleration>0.25</nominal_drive_acceleration>
        <max_drive_acceleration>0.75</max_drive_acceleration>
        <nominal_turn_speed>0.6</nominal_turn_speed>
        <nominal_turn_acceleration>1.5</nominal_turn_acceleration>
        <max_turn_acceleration>2.0</max_turn_acceleration>
        <tire_radius>0.1</tire_radius>
        <base_width>0.3206</base_width>
        <stop_distance>0.75</stop_distance>
        <stop_radius>0.75</stop_radius>
        <nominal_voltage>12.0</nominal_voltage>
        <nominal_capacity>24.0</nominal_capacity>
        <charging_current>5.0</charging_current>
        <mass>20.0</mass>
        <inertia>10.0</inertia>
        <friction_coefficient>0.22</friction_coefficient>
        <nominal_power>20.0</nominal_power>
      </plugin>
      <link name='base_footprint'>
        <pose>0 0 0 0 -0 0</pose>
        <inertial>
          <pose>-0.15 0 0.13 0 -0 0</pose>
          <mass>7</mass>
          <inertia>
            <ixx>0.0594508</ixx>
            <ixy>0</ixy>
            <ixz>-2.77556e-17</ixz>
            <iyy>0.150753</iyy>
            <iyz>0</iyz>
            <izz>0.172704</izz>
          </inertia>
        </inertial>
        <collision name='base_footprint_fixed_joint_lump__base_link_collision'>
          <pose>-0.11 0 0.151 0 -0 0</pose>
          <geometry>
            <box>
              <size>0.398 0.268 0.16</size>
            </box>
          </geometry>
          <max_contacts>10</max_contacts>
          <surface>
            <contact>
              <ode/>
            </contact>
            <bounce/>
            <friction>
              <torsional>
                <ode/>
              </torsional>
              <ode/>
            </friction>
          </surface>
        </collision>
        <collision name='base_footprint_fixed_joint_lump__base_link_collision_1'>
          <pose>-0.136 0 0.248 0 -0 0</pose>
          <geometry>
            <box>
              <size>0.375 0.268 0.034</size>
            </box>
          </geometry>
          <max_contacts>10</max_contacts>
          <surface>
            <contact>
              <ode/>
            </contact>
            <bounce/>
            <friction>
              <torsional>
                <ode/>
              </torsional>
              <ode/>
            </friction>
          </surface>
        </collision>
        <collision name='base_footprint_fixed_joint_lump__base_link_collision_2'>
          <pose>-0.279 0.169 0.106 0 -0 0</pose>
          <geometry>
            <box>
              <size>0.1 0.07 0.07</size>
            </box>
          </geometry>
          <max_contacts>10</max_contacts>
          <surface>
            <contact>
              <ode/>
            </contact>
            <bounce/>
            <friction>
              <torsional>
                <ode/>
              </torsional>
              <ode/>
            </friction>
          </surface>
        </collision>
        <collision name='base_footprint_fixed_joint_lump__base_link_collision_3'>
          <pose>-0.279 -0.169 0.106 0 -0 0</pose>
          <geometry>
            <box>
              <size>0.1 0.07 0.07</size>
            </box>
          </geometry>
          <max_contacts>10</max_contacts>
          <surface>
            <contact>
              <ode/>
            </contact>
            <bounce/>
            <friction>
              <torsional>
                <ode/>
              </torsional>
              <ode/>
            </friction>
          </surface>
        </collision>
        <collision name='base_footprint_fixed_joint_lump__left_caster_wheel_collision_4'>
          <pose>-0.3 0.169 0.04 0 -0 0</pose>
          <geometry>
            <sphere>
              <radius>0.04</radius>
            </sphere>
          </geometry>
          <surface>
            <contact>
              <ode>
                <kp>1e+08</kp>
                <min_depth>0.005</min_depth>
              </ode>
            </contact>
            <friction>
              <ode>
                <mu>0</mu>
                <mu2>0</mu2>
              </ode>
              <torsional>
                <ode/>
              </torsional>
            </friction>
            <bounce/>
          </surface>
          <max_contacts>10</max_contacts>
        </collision>
        <collision name='base_footprint_fixed_joint_lump__raspicam_collision_5'>
          <pose>0.05 0.085 0.245 0 -1.15192 3.1415</pose>
          <geometry>
            <box>
              <size>0.03 0.026 0.016</size>
            </box>
          </geometry>
          <max_contacts>10</max_contacts>
          <surface>
            <contact>
              <ode/>
            </contact>
            <bounce/>
            <friction>
              <torsional>
                <ode/>
              </torsional>
              <ode/>
            </friction>
          </surface>
        </collision>
        <collision name='base_footprint_fixed_joint_lump__right_caster_wheel_collision_6'>
          <pose>-0.3 -0.169 0.04 0 -0 0</pose>
          <geometry>
            <sphere>
              <radius>0.04</radius>
            </sphere>
          </geometry>
          <surface>
            <contact>
              <ode>
                <kp>1e+08</kp>
                <min_depth>0.005</min_depth>
              </ode>
            </contact>
            <friction>
              <ode>
                <mu>0</mu>
                <mu2>0</mu2>
              </ode>
              <torsional>
                <ode/>
              </torsional>
            </friction>
            <bounce/>
          </surface>
          <max_contacts>10</max_contacts>
        </collision>
        <collision name='base_footprint_fixed_joint_lump__sonar_0_collision_7'>
          <pose>0.01 -0.14 0.25 0 0 -1.5708</pose>
          <geometry>
            <box>
              <size>0.02 0.044 0.021</size>
            </box>
          </geometry>
          <surface>
            <contact>
              <ode/>
            </contact>
            <friction>
              <ode/>
              <torsional>
                <ode/>
              </torsional>
            </friction>
            <bounce/>
          </surface>
          <max_contacts>10</max_contacts>
        </collision>
        <collision name='base_footprint_fixed_joint_lump__sonar_1_collision_8'>
          <pose>0.08 -0.07 0.25 0 -0 0.785</pose>
          <geometry>
            <box>
              <size>0.02 0.044 0.021</size>
            </box>
          </geometry>
          <surface>
            <contact>
              <ode/>
            </contact>
            <friction>
              <ode/>
              <torsional>
                <ode/>
              </torsional>
            </friction>
            <bounce/>
          </surface>
          <max_contacts>10</max_contacts>
        </collision>
        <collision name='base_footprint_fixed_joint_lump__sonar_2_collision_9'>
          <pose>0.08 -0.01 0.25 0 0 -0.785</pose>
          <geometry>
            <box>
              <size>0.02 0.044 0.021</size>
            </box>
          </geometry>
          <surface>
            <contact>
              <ode/>
            </contact>
            <friction>
              <ode/>
              <torsional>
                <ode/>
              </torsional>
            </friction>
            <bounce/>
          </surface>
          <max_contacts>10</max_contacts>
        </collision>
        <collision name='base_footprint_fixed_joint_lump__sonar_3_collision_10'>
          <pose>0.08 0.04 0.25 0 -0 0</pose>
          <geometry>
            <box>
              <size>0.02 0.044 0.021</size>
            </box>
          </geometry>
          <surface>
            <contact>
              <ode/>
            </contact>
            <friction>
              <ode/>
              <torsional>
                <ode/>
              </torsional>
            </friction>
            <bounce/>
          </surface>
          <max_contacts>10</max_contacts>
        </collision>
        <collision name='base_footprint_fixed_joint_lump__sonar_4_collision_11'>
          <pose>0.01 0.14 0.25 0 -0 1.5708</pose>
          <geometry>
            <box>
              <size>0.02 0.044 0.021</size>
            </box>
          </geometry>
          <surface>
            <contact>
              <ode/>
            </contact>
            <friction>
              <ode/>
              <torsional>
                <ode/>
              </torsional>
            </friction>
            <bounce/>
          </surface>
          <max_contacts>10</max_contacts>
        </collision>
        <visual name='base_footprint_fixed_joint_lump__base_link_visual'>
          <pose>-0.11 0 0.071 0 -0 0</pose>
          <geometry>
            <mesh>
              <scale>1 1 1</scale>
              <uri>model://TinyRobot/meshes/tinyRobot_body.dae</uri>
            </mesh>
          </geometry>
        </visual>
        <visual name='base_footprint_fixed_joint_lump__base_link_visual_1'>
          <pose>-0.279 0.17 0.09 0 -0 -3.14159</pose>
          <geometry>
            <mesh>
              <scale>1 1 1</scale>
              <uri>model://TinyRobot/meshes/caster_wheel.dae</uri>
            </mesh>
          </geometry>
        </visual>
        <visual name='base_footprint_fixed_joint_lump__base_link_visual_2'>
          <pose>-0.279 -0.17 0.09 0 -0 -3.14159</pose>
          <geometry>
            <mesh>
              <scale>1 1 1</scale>
              <uri>model://TinyRobot/meshes/caster_wheel.dae</uri>
            </mesh>
          </geometry>
        </visual>
        <velocity_decay/>
        <velocity_decay/>
        <velocity_decay/>
        <velocity_decay/>
        <self_collide>0</self_collide>
        <enable_wind>0</enable_wind>
        <kinematic>0</kinematic>
      </link>
      <link name='left_wheel'>
        <pose>0 0.163 0.1 0 -0 1.5708</pose>
        <inertial>
          <pose>0 0 0 3.14159 1.57079 3.14159</pose>
          <mass>3.34</mass>
          <inertia>
            <ixx>0.00904583</ixx>
            <ixy>0</ixy>
            <ixz>0</ixz>
            <iyy>0.00904583</iyy>
            <iyz>0</iyz>
            <izz>0.0167</izz>
          </inertia>
        </inertial>
        <collision name='left_wheel_collision'>
          <pose>0 0 0 3.14159 1.57079 3.14159</pose>
          <geometry>
            <sphere>
              <radius>0.1</radius>
            </sphere>
          </geometry>
          <surface>
            <contact>
              <ode>
                <kp>1e+07</kp>
                <kd>1</kd>
              </ode>
            </contact>
            <friction>
              <ode>
                <mu>1</mu>
                <mu2>1</mu2>
                <fdir1>0 0 1</fdir1>
              </ode>
              <torsional>
                <ode/>
              </torsional>
            </friction>
            <bounce/>
          </surface>
          <max_contacts>10</max_contacts>
        </collision>
        <visual name='left_wheel_visual'>
          <pose>-0.071 0 0 0 -0 0</pose>
          <geometry>
            <mesh>
              <scale>1 1 1</scale>
              <uri>model://TinyRobot/meshes/front_wheel.dae</uri>
            </mesh>
          </geometry>
        </visual>
        <gravity>1</gravity>
        <velocity_decay/>
        <self_collide>0</self_collide>
        <enable_wind>0</enable_wind>
        <kinematic>0</kinematic>
      </link>
      <joint name='joint_tire_left' type='revolute'>
        <child>left_wheel</child>
        <parent>base_footprint</parent>
        <axis>
          <xyz expressed_in='__model__'>0 1 0</xyz>
          <limit>
            <lower>-1e+16</lower>
            <upper>1e+16</upper>
          </limit>
          <dynamics>
            <spring_reference>0</spring_reference>
            <spring_stiffness>0</spring_stiffness>
          </dynamics>
        </axis>
      </joint>
      <link name='right_wheel'>
        <pose>0 -0.163 0.1 0 -0 1.5708</pose>
        <inertial>
          <pose>0 0 0 3.14159 1.57079 3.14159</pose>
          <mass>3.34</mass>
          <inertia>
            <ixx>0.00904583</ixx>
            <ixy>0</ixy>
            <ixz>0</ixz>
            <iyy>0.00904583</iyy>
            <iyz>0</iyz>
            <izz>0.0167</izz>
          </inertia>
        </inertial>
        <collision name='right_wheel_collision'>
          <pose>0 0 0 3.14159 1.57079 3.14159</pose>
          <geometry>
            <sphere>
              <radius>0.1</radius>
            </sphere>
          </geometry>
          <surface>
            <contact>
              <ode>
                <kp>1e+07</kp>
                <kd>1</kd>
              </ode>
            </contact>
            <friction>
              <ode>
                <mu>1</mu>
                <mu2>1</mu2>
                <fdir1>0 0 1</fdir1>
              </ode>
              <torsional>
                <ode/>
              </torsional>
            </friction>
            <bounce/>
          </surface>
          <max_contacts>10</max_contacts>
        </collision>
        <visual name='right_wheel_visual'>
          <pose>0.071 0 0 -3.14159 -0 -3.14159</pose>
          <geometry>
            <mesh>
              <scale>1 1 1</scale>
              <uri>model://TinyRobot/meshes/front_wheel.dae</uri>
            </mesh>
          </geometry>
        </visual>
        <gravity>1</gravity>
        <velocity_decay/>
        <self_collide>0</self_collide>
        <enable_wind>0</enable_wind>
        <kinematic>0</kinematic>
      </link>
      <joint name='joint_tire_right' type='revolute'>
        <child>right_wheel</child>
        <parent>base_footprint</parent>
        <axis>
          <xyz expressed_in='__model__'>0 1 0</xyz>
          <limit>
            <lower>-1e+16</lower>
            <upper>1e+16</upper>
          </limit>
          <dynamics>
            <spring_reference>0</spring_reference>
            <spring_stiffness>0</spring_stiffness>
          </dynamics>
        </axis>
      </joint>
      <static>0</static>
      <pose>20.4237 -5.3121 0 0 0 -0.696091</pose>
    </model>
    <model name='main_door'>
      <pose>13.132 -2.57949 0 0 0 -3.12027</pose>
      <link name='right'>
        <pose>-0.473864 0 1.11 0 -0 0</pose>
        <visual name='right_visual'>
          <geometry>
            <box>
              <size>0.937729 0.03 2.2</size>
            </box>
          </geometry>
          <material>
            <ambient>0.5 0.25 0 0.6</ambient>
            <diffuse>0.5 0.25 0 0.6</diffuse>
          </material>
        </visual>
        <collision name='right_collision'>
          <geometry>
            <box>
              <size>0.937729 0.03 2.2</size>
            </box>
          </geometry>
          <surface>
            <contact>
              <collide_bitmask>2</collide_bitmask>
              <ode/>
            </contact>
            <bounce/>
            <friction>
              <torsional>
                <ode/>
              </torsional>
              <ode/>
            </friction>
          </surface>
          <max_contacts>10</max_contacts>
        </collision>
        <inertial>
          <mass>50</mass>
          <inertia>
            <ixx>20.1704</ixx>
            <iyy>23.8306</iyy>
            <izz>3.66765</izz>
            <ixy>0</ixy>
            <ixz>0</ixz>
            <iyz>0</iyz>
          </inertia>
          <pose>0 0 0 0 -0 0</pose>
        </inertial>
        <self_collide>0</self_collide>
        <enable_wind>0</enable_wind>
        <kinematic>0</kinematic>
      </link>
      <joint name='right_joint' type='revolute'>
        <parent>world</parent>
        <child>right</child>
        <axis>
          <xyz>0 0 1</xyz>
          <limit>
            <lower>0</lower>
            <upper>1.57</upper>
          </limit>
          <dynamics>
            <spring_reference>0</spring_reference>
            <spring_stiffness>0</spring_stiffness>
          </dynamics>
        </axis>
        <pose>-0.473864 0 0 0 -0 0</pose>
      </joint>
      <link name='left'>
        <pose>0.473864 0 1.11 0 -0 0</pose>
        <visual name='left_visual'>
          <geometry>
            <box>
              <size>0.937729 0.03 2.2</size>
            </box>
          </geometry>
          <material>
            <ambient>0.5 0.25 0 0.6</ambient>
            <diffuse>0.5 0.25 0 0.6</diffuse>
          </material>
        </visual>
        <collision name='left_collision'>
          <geometry>
            <box>
              <size>0.937729 0.03 2.2</size>
            </box>
          </geometry>
          <surface>
            <contact>
              <collide_bitmask>2</collide_bitmask>
              <ode/>
            </contact>
            <bounce/>
            <friction>
              <torsional>
                <ode/>
              </torsional>
              <ode/>
            </friction>
          </surface>
          <max_contacts>10</max_contacts>
        </collision>
        <inertial>
          <mass>50</mass>
          <inertia>
            <ixx>20.1704</ixx>
            <iyy>23.8306</iyy>
            <izz>3.66765</izz>
            <ixy>0</ixy>
            <ixz>0</ixz>
            <iyz>0</iyz>
          </inertia>
          <pose>0 0 0 0 -0 0</pose>
        </inertial>
        <self_collide>0</self_collide>
        <enable_wind>0</enable_wind>
        <kinematic>0</kinematic>
      </link>
      <joint name='left_joint' type='revolute'>
        <parent>world</parent>
        <child>left</child>
        <axis>
          <xyz>0 0 1</xyz>
          <limit>
            <lower>-1.57</lower>
            <upper>0</upper>
          </limit>
          <dynamics>
            <spring_reference>0</spring_reference>
            <spring_stiffness>0</spring_stiffness>
          </dynamics>
        </axis>
        <pose>0.473864 0 0 0 -0 0</pose>
      </joint>
      <plugin name='door' filename='libdoor.so'>
        <v_max_door>0.5</v_max_door>
        <a_max_door>0.3</a_max_door>
        <a_nom_door>0.15</a_nom_door>
        <dx_min_door>0.01</dx_min_door>
        <f_max_door>500.0</f_max_door>
        <door name='main_door' type='DoubleSwingDoor' left_joint_name='left_joint' right_joint_name='right_joint'/>
      </plugin>
    </model>
    <model name='coe_door'>
      <pose>8.07769 -5.89834 0 0 -0 1.156</pose>
      <plugin name='door' filename='libdoor.so'>
        <v_max_door>0.5</v_max_door>
        <a_max_door>0.3</a_max_door>
        <a_nom_door>0.15</a_nom_door>
        <dx_min_door>0.01</dx_min_door>
        <f_max_door>500.0</f_max_door>
        <door name='coe_door' type='SwingDoor' left_joint_name='left_joint' right_joint_name='empty_joint'/>
      </plugin>
      <link name='left'>
        <pose>0 0 1.11 0 -0 0</pose>
        <visual name='left_visual'>
          <geometry>
            <box>
              <size>0.876603 0.03 2.2</size>
            </box>
          </geometry>
          <material>
            <ambient>0.5 0.25 0 0.6</ambient>
            <diffuse>0.5 0.25 0 0.6</diffuse>
          </material>
        </visual>
        <collision name='left_collision'>
          <geometry>
            <box>
              <size>0.876603 0.03 2.2</size>
            </box>
          </geometry>
          <surface>
            <contact>
              <collide_bitmask>2</collide_bitmask>
              <ode/>
            </contact>
            <bounce/>
            <friction>
              <torsional>
                <ode/>
              </torsional>
              <ode/>
            </friction>
          </surface>
          <max_contacts>10</max_contacts>
        </collision>
        <inertial>
          <mass>50</mass>
          <inertia>
            <ixx>20.1704</ixx>
            <iyy>23.3685</iyy>
            <izz>3.20555</izz>
            <ixy>0</ixy>
            <ixz>0</ixz>
            <iyz>0</iyz>
          </inertia>
          <pose>0 0 0 0 -0 0</pose>
        </inertial>
        <self_collide>0</self_collide>
        <enable_wind>0</enable_wind>
        <kinematic>0</kinematic>
      </link>
      <joint name='left_joint' type='revolute'>
        <parent>world</parent>
        <child>left</child>
        <axis>
          <xyz>0 0 1</xyz>
          <limit>
            <lower>-1.57</lower>
            <upper>0</upper>
          </limit>
          <dynamics>
            <spring_reference>0</spring_reference>
            <spring_stiffness>0</spring_stiffness>
          </dynamics>
        </axis>
        <pose>0.443301 0 0 0 -0 0</pose>
      </joint>
    </model>
    <model name='hardware_door'>
      <pose>19.4501 -10.3192 0 0 0 -1.57606</pose>
      <plugin name='door' filename='libdoor.so'>
        <v_max_door>0.5</v_max_door>
        <a_max_door>0.3</a_max_door>
        <a_nom_door>0.15</a_nom_door>
        <dx_min_door>0.01</dx_min_door>
        <f_max_door>500.0</f_max_door>
        <door name='hardware_door' type='SwingDoor' left_joint_name='left_joint' right_joint_name='empty_joint'/>
      </plugin>
      <link name='left'>
        <pose>0 0 1.11 0 -0 0</pose>
        <visual name='left_visual'>
          <geometry>
            <box>
              <size>0.879262 0.03 2.2</size>
            </box>
          </geometry>
          <material>
            <ambient>0.5 0.25 0 0.6</ambient>
            <diffuse>0.5 0.25 0 0.6</diffuse>
          </material>
        </visual>
        <collision name='left_collision'>
          <geometry>
            <box>
              <size>0.879262 0.03 2.2</size>
            </box>
          </geometry>
          <surface>
            <contact>
              <collide_bitmask>2</collide_bitmask>
              <ode/>
            </contact>
            <bounce/>
            <friction>
              <torsional>
                <ode/>
              </torsional>
              <ode/>
            </friction>
          </surface>
          <max_contacts>10</max_contacts>
        </collision>
        <inertial>
          <mass>50</mass>
          <inertia>
            <ixx>20.1704</ixx>
            <iyy>23.3879</iyy>
            <izz>3.22501</izz>
            <ixy>0</ixy>
            <ixz>0</ixz>
            <iyz>0</iyz>
          </inertia>
          <pose>0 0 0 0 -0 0</pose>
        </inertial>
        <self_collide>0</self_collide>
        <enable_wind>0</enable_wind>
        <kinematic>0</kinematic>
      </link>
      <joint name='left_joint' type='revolute'>
        <parent>world</parent>
        <child>left</child>
        <axis>
          <xyz>0 0 1</xyz>
          <limit>
            <lower>-1.57</lower>
            <upper>0</upper>
          </limit>
          <dynamics>
            <spring_reference>0</spring_reference>
            <spring_stiffness>0</spring_stiffness>
          </dynamics>
        </axis>
        <pose>0.444631 0 0 0 -0 0</pose>
      </joint>
    </model>
    <model name='building_L1'>
      <static>1</static>
      <link name='floor_1'>
        <visual name='visual'>
          <geometry>
            <mesh>
              <uri>model://building_L1/meshes/floor_1.obj</uri>
            </mesh>
          </geometry>
          <material>
            <diffuse>1 1 1 1</diffuse>
            <specular>0.1 0.1 0.1 1</specular>
            <pbr>
              <metal>
                <metalness>0.0</metalness>
                <albedo_map>model://building_L1/meshes/blue_linoleum.png</albedo_map>
              </metal>
            </pbr>
            <script>
              <uri>model://building_L1/meshes/</uri>
              <name>floor_1_Diffuse</name>
            </script>
          </material>
        </visual>
        <collision name='collision'>
          <geometry>
            <mesh>
              <uri>model://building_L1/meshes/floor_1.obj</uri>
            </mesh>
          </geometry>
          <surface>
            <contact>
              <collide_bitmask>1</collide_bitmask>
              <ode/>
            </contact>
            <bounce/>
            <friction>
              <torsional>
                <ode/>
              </torsional>
              <ode/>
            </friction>
          </surface>
          <max_contacts>10</max_contacts>
        </collision>
        <self_collide>0</self_collide>
        <enable_wind>0</enable_wind>
        <kinematic>0</kinematic>
      </link>
      <link name='wall_1'>
        <visual name='wall_1'>
          <geometry>
            <mesh>
              <uri>model://building_L1/meshes/wall_1.obj</uri>
            </mesh>
          </geometry>
          <material>
            <diffuse>1 1 1 1</diffuse>
            <specular>0.1 0.1 0.1 1</specular>
            <pbr>
              <metal>
                <metalness>0.0</metalness>
                <albedo_map>model://building_L1/meshes/default.png</albedo_map>
              </metal>
            </pbr>
            <script>
              <uri>model://building_L1/meshes/</uri>
              <name>wall_1_Diffuse</name>
            </script>
          </material>
        </visual>
        <collision name='collision'>
          <geometry>
            <mesh>
              <uri>model://building_L1/meshes/wall_1.obj</uri>
            </mesh>
          </geometry>
          <surface>
            <contact>
              <collide_bitmask>1</collide_bitmask>
              <ode/>
            </contact>
            <bounce/>
            <friction>
              <torsional>
                <ode/>
              </torsional>
              <ode/>
            </friction>
          </surface>
          <max_contacts>10</max_contacts>
        </collision>
        <self_collide>0</self_collide>
        <enable_wind>0</enable_wind>
        <kinematic>0</kinematic>
      </link>
      <pose>0 0 0 0 -0 0</pose>
    </model>
    <gravity>0 0 -9.8</gravity>
    <magnetic_field>6e-06 2.3e-05 -4.2e-05</magnetic_field>
    <atmosphere type='adiabatic'/>
    <physics type='ode'>
      <max_step_size>0.001</max_step_size>
      <real_time_factor>1</real_time_factor>
      <real_time_update_rate>1000</real_time_update_rate>
    </physics>
    <wind/>
    <spherical_coordinates>
      <surface_model>EARTH_WGS84</surface_model>
      <latitude_deg>0</latitude_deg>
      <longitude_deg>0</longitude_deg>
      <elevation>0</elevation>
      <heading_deg>0</heading_deg>
    </spherical_coordinates>
    <state world_name='world'>
      <sim_time>222 767000000</sim_time>
      <real_time>182 708649437</real_time>
      <wall_time>1622795000 971786096</wall_time>
      <iterations>180979</iterations>
      <model name='AdjTable'>
        <pose>11.7885 -5.97975 0 0 0 -3.12188</pose>
        <scale>1 1 1</scale>
        <link name='body'>
          <pose>11.7885 -5.97975 0 0 -0 -3.12188</pose>
          <velocity>0 0 0 0 -0 0</velocity>
          <acceleration>0 0 0 0 -0 0</acceleration>
          <wrench>0 0 0 0 -0 0</wrench>
        </link>
      </model>
      <model name='AdjTable_10'>
        <pose>13.0065 -5.56573 0 0 -0 1.5914</pose>
        <scale>1 1 1</scale>
        <link name='body'>
          <pose>13.0065 -5.56573 0 0 -0 1.5914</pose>
          <velocity>0 0 0 0 -0 0</velocity>
          <acceleration>0 0 0 0 -0 0</acceleration>
          <wrench>0 0 0 0 -0 0</wrench>
        </link>
      </model>
      <model name='AdjTable_3'>
        <pose>14.2449 -5.94148 0 0 0 -3.12378</pose>
        <scale>1 1 1</scale>
        <link name='body'>
          <pose>14.2449 -5.94148 0 0 -0 -3.12378</pose>
          <velocity>0 0 0 0 -0 0</velocity>
          <acceleration>0 0 0 0 -0 0</acceleration>
          <wrench>0 0 0 0 -0 0</wrench>
        </link>
      </model>
      <model name='AdjTable_4'>
        <pose>6.73419 -9.67534 0 0 -0 1.0878</pose>
        <scale>1 1 1</scale>
        <link name='body'>
          <pose>6.73419 -9.67534 0 0 -0 1.0878</pose>
          <velocity>0 0 0 0 -0 0</velocity>
          <acceleration>0 0 0 0 -0 0</acceleration>
          <wrench>0 0 0 0 -0 0</wrench>
        </link>
      </model>
      <model name='Coke'>
        <pose>17.7044 -5.29153 0 4.7e-05 -1.1e-05 1.57078</pose>
        <scale>1 1 1</scale>
        <link name='body'>
          <pose>17.7044 -5.29153 0 4.7e-05 -1.1e-05 1.57078</pose>
          <velocity>-0 0 0.000909 0.017045 0.028852 0</velocity>
          <acceleration>3e-06 -1.6e-05 -8.02556 0.379503 -0.52372 -3.13705</acceleration>
          <wrench>3e-06 -1.6e-05 -8.02556 0 -0 0</wrench>
        </link>
      </model>
      <model name='ConfTable'>
        <pose>5.24861 -7.38191 0 0 -0 1.1017</pose>
        <scale>1 1 1</scale>
        <link name='body'>
          <pose>5.24861 -7.38191 0 0 -0 1.1017</pose>
          <velocity>0 0 0 0 -0 0</velocity>
          <acceleration>0 0 0 0 -0 0</acceleration>
          <wrench>0 0 0 0 -0 0</wrench>
        </link>
      </model>
      <model name='Drawer'>
        <pose>6.11121 -10.5644 0 0 -0 1.1104</pose>
        <scale>1 1 1</scale>
        <link name='body'>
          <pose>6.11121 -10.5644 0 0 -0 1.1104</pose>
          <velocity>0 0 0 0 -0 0</velocity>
          <acceleration>0 0 0 0 -0 0</acceleration>
          <wrench>0 0 0 0 -0 0</wrench>
        </link>
      </model>
      <model name='Fridge'>
        <pose>15.9881 -5.75084 0 0 -0 1.5708</pose>
        <scale>1 1 1</scale>
        <link name='body'>
          <pose>15.9881 -5.75084 0 0 -0 1.5708</pose>
          <velocity>0 0 0 0 -0 0</velocity>
          <acceleration>0 0 0 0 -0 0</acceleration>
          <wrench>0 0 0 0 -0 0</wrench>
        </link>
      </model>
      <model name='OfficeChairGrey'>
        <pose>14.2558 -5.54694 0 0 -0 0.0166</pose>
        <scale>1 1 1</scale>
        <link name='body'>
          <pose>14.2558 -5.54694 0 0 -0 0.0166</pose>
          <velocity>0 0 0 0 -0 0</velocity>
          <acceleration>0 0 0 0 -0 0</acceleration>
          <wrench>0 0 0 0 -0 0</wrench>
        </link>
      </model>
      <model name='OfficeChairGrey_11'>
        <pose>11.8429 -5.56464 0 0 -0 0.016</pose>
        <scale>1 1 1</scale>
        <link name='body'>
          <pose>11.8429 -5.56464 0 0 -0 0.016</pose>
          <velocity>0 0 0 0 -0 0</velocity>
          <acceleration>0 0 0 0 -0 0</acceleration>
          <wrench>0 0 0 0 -0 0</wrench>
        </link>
      </model>
      <model name='RecTable'>
        <pose>21.8765 -4.46735 0 0 -0 0</pose>
        <scale>1 1 1</scale>
        <link name='body'>
          <pose>21.8765 -4.46735 0 0 -0 0</pose>
          <velocity>0 0 0 0 -0 0</velocity>
          <acceleration>0 0 0 0 -0 0</acceleration>
          <wrench>0 0 0 0 -0 0</wrench>
        </link>
      </model>
      <model name='aws_robomaker_warehouse_ClutteringA_01'>
        <pose>13.5818 -10.8788 0 0 -0 0</pose>
        <scale>1 1 1</scale>
        <link name='link'>
          <pose>13.5818 -10.8788 0 0 -0 0</pose>
          <velocity>0 0 0 0 -0 0</velocity>
          <acceleration>0 0 0 0 -0 0</acceleration>
          <wrench>0 0 0 0 -0 0</wrench>
        </link>
      </model>
      <model name='aws_robomaker_warehouse_ShelfE_01'>
        <pose>16.9283 -10.9641 0 0 -0 0</pose>
        <scale>1 1 1</scale>
        <link name='link'>
          <pose>16.9283 -10.9641 0 0 -0 0</pose>
          <velocity>0 0 0 0 -0 0</velocity>
          <acceleration>0 0 0 0 -0 0</acceleration>
          <wrench>0 0 0 0 -0 0</wrench>
        </link>
      </model>
      <model name='building_L1'>
        <pose>0 0 0 0 -0 0</pose>
        <scale>1 1 1</scale>
        <link name='floor_1'>
          <pose>0 0 0 0 -0 0</pose>
          <velocity>0 0 0 0 -0 0</velocity>
          <acceleration>0 0 0 0 -0 0</acceleration>
          <wrench>0 0 0 0 -0 0</wrench>
        </link>
        <link name='wall_1'>
          <pose>0 0 0 0 -0 0</pose>
          <velocity>0 0 0 0 -0 0</velocity>
          <acceleration>0 0 0 0 -0 0</acceleration>
          <wrench>0 0 0 0 -0 0</wrench>
        </link>
      </model>
      <model name='coe_door'>
        <pose>8.07769 -5.89834 0 0 -0 1.156</pose>
        <scale>1 1 1</scale>
        <link name='left'>
          <pose>8.07769 -5.89834 1.11 0 -0 1.156</pose>
          <velocity>-0 0 0 0 -0 0</velocity>
          <acceleration>-0 -0 0 0 -0 0</acceleration>
          <wrench>-0 -0 0 0 -0 0</wrench>
        </link>
      </model>
      <model name='coke_dispenser'>
        <pose>17.7044 -5.28942 0 0 -0 1.5708</pose>
        <scale>1 1 1</scale>
        <link name='visual_link'>
          <pose>17.7044 -5.28942 0.05 0 -0 1.5708</pose>
          <velocity>0 0 0 0 -0 0</velocity>
          <acceleration>0 0 0 0 -0 0</acceleration>
          <wrench>0 0 0 0 -0 0</wrench>
        </link>
      </model>
      <model name='coke_ingestor'>
        <pose>22.5427 -7.61045 0.805 0 -0 1.5708</pose>
        <scale>1 1 1</scale>
        <link name='visual_link'>
          <pose>22.5427 -7.61045 0.855 0 -0 1.5708</pose>
          <velocity>0 0 0 0 -0 0</velocity>
          <acceleration>0 0 0 0 -0 0</acceleration>
          <wrench>0 0 0 0 -0 0</wrench>
        </link>
      </model>
      <model name='hardware_door'>
        <pose>19.4501 -10.3192 0 0 0 -1.57606</pose>
        <scale>1 1 1</scale>
        <link name='left'>
          <pose>19.4501 -10.3192 1.11 0 0 -1.57606</pose>
          <velocity>-0 -0 0 0 -0 0</velocity>
          <acceleration>0 -0 0 0 -0 0</acceleration>
          <wrench>0 -0 0 0 -0 0</wrench>
        </link>
      </model>
      <model name='main_door'>
        <pose>13.132 -2.57949 0 0 -0 -3.12027</pose>
        <scale>1 1 1</scale>
        <link name='left'>
          <pose>12.6582 -2.58959 1.11 0 0 -3.12027</pose>
          <velocity>0 -0 0 0 -0 0</velocity>
          <acceleration>0 -0 0 0 -0 0</acceleration>
          <wrench>0 -0 0 0 -0 0</wrench>
        </link>
        <link name='right'>
          <pose>13.6058 -2.56939 1.11 0 -0 -3.12027</pose>
          <velocity>0 -0 0 0 -0 0</velocity>
          <acceleration>0 -0 0 0 -0 0</acceleration>
          <wrench>0 -0 0 0 -0 0</wrench>
        </link>
      </model>
      <model name='tinyRobot1'>
        <pose>10.4331 -5.57487 -5e-06 0 1.6e-05 1.32863</pose>
        <scale>1 1 1</scale>
        <link name='base_footprint'>
          <pose>10.4331 -5.57487 -5e-06 0 1.6e-05 1.32863</pose>
          <velocity>0 2e-06 3.1e-05 9.4e-05 -2.3e-05 0</velocity>
          <acceleration>0 -0 -0 0 -0 0</acceleration>
          <wrench>0 -0 -0 0 -0 0</wrench>
        </link>
        <link name='left_wheel'>
          <pose>10.2748 -5.53578 0.099995 0.002 1e-06 2.89943</pose>
          <velocity>-2e-06 -8e-06 3.1e-05 8e-05 -2e-05 0</velocity>
          <acceleration>0 -0 0 0 -0 0</acceleration>
          <wrench>0 -0 0 0 -0 0</wrench>
        </link>
        <link name='right_wheel'>
          <pose>10.5913 -5.61396 0.099995 0.002187 1e-06 2.89943</pose>
          <velocity>-2e-06 -8e-06 3.1e-05 8e-05 -2e-05 0</velocity>
          <acceleration>0 -0 -0 0 -0 0</acceleration>
          <wrench>0 -0 -0 0 -0 0</wrench>
        </link>
      </model>
      <model name='tinyRobot2'>
        <pose>20.4239 -5.3122 -5e-06 0 1.6e-05 -0.696013</pose>
        <scale>1 1 1</scale>
        <link name='base_footprint'>
          <pose>20.4239 -5.3122 -5e-06 0 1.6e-05 -0.696013</pose>
          <velocity>1e-06 -1e-06 3.1e-05 -6.2e-05 -7.4e-05 0</velocity>
          <acceleration>0 -0 0 0 1e-06 0</acceleration>
          <wrench>1e-06 -0 1e-06 0 -0 0</wrench>
        </link>
        <link name='left_wheel'>
          <pose>20.5284 -5.18712 0.099995 0.002026 1e-06 0.874787</pose>
          <velocity>-6e-06 5e-06 3.1e-05 -5.3e-05 -6.3e-05 0</velocity>
          <acceleration>0 -0 -0 0 -0 0</acceleration>
          <wrench>0 -0 -0 0 -0 0</wrench>
        </link>
        <link name='right_wheel'>
          <pose>20.3193 -5.43729 0.099995 0.002162 1e-06 0.874787</pose>
          <velocity>-6e-06 5e-06 3.1e-05 -5.3e-05 -6.3e-05 0</velocity>
          <acceleration>0 -0 0 0 -0 0</acceleration>
          <wrench>0 -0 0 0 -0 0</wrench>
        </link>
      </model>
      <light name='sun'>
        <pose>0 0 10 0 -0 0</pose>
      </light>
    </state>
    <model name='aws_robomaker_warehouse_ShelfE_01'>
      <link name='link'>
        <inertial>
          <mass>30</mass>
          <inertia>
            <ixx>907.144</ixx>
            <ixy>0</ixy>
            <ixz>0</ixz>
            <iyy>104.95</iyy>
            <iyz>0</iyz>
            <izz>824.248</izz>
          </inertia>
        </inertial>
        <collision name='collision'>
          <geometry>
            <mesh>
              <uri>model://aws_robomaker_warehouse_ShelfE_01/meshes/aws_robomaker_warehouse_ShelfE_01_collision.DAE</uri>
              <scale>1 1 1</scale>
            </mesh>
          </geometry>
          <surface>
            <friction>
              <ode>
                <mu>0.2</mu>
                <mu2>0.2</mu2>
                <fdir1>0 0 0</fdir1>
                <slip1>0</slip1>
                <slip2>0</slip2>
              </ode>
              <torsional>
                <ode/>
              </torsional>
            </friction>
            <contact>
              <ode/>
            </contact>
            <bounce/>
          </surface>
          <max_contacts>10</max_contacts>
        </collision>
        <visual name='visual'>
          <geometry>
            <mesh>
              <uri>model://aws_robomaker_warehouse_ShelfE_01/meshes/aws_robomaker_warehouse_ShelfE_01_visual.DAE</uri>
            </mesh>
          </geometry>
          <meta>
            <layer>1</layer>
          </meta>
        </visual>
        <self_collide>0</self_collide>
        <enable_wind>0</enable_wind>
        <kinematic>0</kinematic>
      </link>
      <static>1</static>
      <pose>16.9283 -10.9641 0 0 -0 0</pose>
    </model>
    <model name='aws_robomaker_warehouse_ClutteringA_01'>
      <link name='link'>
        <inertial>
          <mass>2</mass>
          <inertia>
            <ixx>0.841</ixx>
            <ixy>0</ixy>
            <ixz>0</ixz>
            <iyy>0.954</iyy>
            <iyz>0</iyz>
            <izz>1.422</izz>
          </inertia>
        </inertial>
        <collision name='collision'>
          <geometry>
            <mesh>
              <uri>model://aws_robomaker_warehouse_ClutteringA_01/meshes/aws_robomaker_warehouse_ClutteringA_01_collision.DAE</uri>
              <scale>1 1 1</scale>
            </mesh>
          </geometry>
          <surface>
            <friction>
              <ode>
                <mu>0.6</mu>
                <mu2>0.6</mu2>
                <fdir1>0 0 0</fdir1>
                <slip1>0</slip1>
                <slip2>0</slip2>
              </ode>
              <torsional>
                <coefficient>1</coefficient>
                <patch_radius>0</patch_radius>
                <surface_radius>0</surface_radius>
                <use_patch_radius>1</use_patch_radius>
                <ode>
                  <slip>0</slip>
                </ode>
              </torsional>
            </friction>
            <contact>
              <ode/>
            </contact>
            <bounce/>
          </surface>
          <max_contacts>10</max_contacts>
        </collision>
        <visual name='visual'>
          <geometry>
            <mesh>
              <uri>model://aws_robomaker_warehouse_ClutteringA_01/meshes/aws_robomaker_warehouse_ClutteringA_01_visual.DAE</uri>
            </mesh>
          </geometry>
          <meta>
            <layer>1</layer>
          </meta>
        </visual>
        <self_collide>0</self_collide>
        <enable_wind>0</enable_wind>
        <kinematic>0</kinematic>
      </link>
      <static>1</static>
      <pose>13.5818 -10.8788 0 0 -0 0</pose>
    </model>
    <rmf_charger_waypoints name='charger_waypoints'>
      <rmf_vertex name='tinyRobot1_charger' x='10.433053704916215' y='-5.5750955876973505' level='L1'/>
      <rmf_vertex name='tinyRobot2_charger' x='20.423692180237488' y='-5.312098057266895' level='L1'/>
    </rmf_charger_waypoints>
  </world>
</sdf>
